reports/10level_train_11-1_11-21_test_11-22_11-30.txt
    code_list = [
        # 中证A50十大权重
        '600519sh',  # 贵州茅台
        '300750sz',  # 宁德时代
        '601318sh',  # 中国平安
        '600036sh',  # 招商银行
        '600900sh',  # 长江电力
        '000333sz',  # 美的集团
        '002594sz',  # 比亚迪
        '601899sh',  # 紫金矿业
        '600030sh',  # 中信证券
        '600276sh',  # 恒瑞医药
    ]

    downsample_args = {
        "strategy": "fraction",
        "value": 0.2,
        "random_state": 42
    }

    train_df, test_df = load_data(
        train_data_folder_list=[
            "data_202111/2D_data_11-1_11-7_10level",
            "data_202111/2D_data_11-8_11-14_10level",
            "data_202111/2D_data_11-15_11-21_10level"
        ],
        test_data_folder_list=["data_202111/2D_data_11-22_11-30_10level"],
        code_list=code_list,
        downsample_args=downsample_args
    )

    # === Random Forest ===
    print("\nTraining Random Forest...")
    start = time.time()
    rf = RandomForestClassifier(
        n_estimators=300,        # 增加树数量，增强模型稳定性
        max_depth=8,            # 控制单棵树复杂度，防止过拟合
        min_samples_split=10,    # 控制分裂，防止小样本暴力分裂
        min_samples_leaf=5,      # 增强泛化能力
        max_features='sqrt',     # 降低相关性提升泛化
        n_jobs=-1,
        random_state=42, 
        verbose=1
    )


训练集大小: (113676, 13440), 测试集大小: (36099, 13440)
训练集标签分布: (array([0., 1.]), array([68918, 44758]))
测试集标签分布: (array([0., 1.]), array([22742, 13357]))

22742 / 36099 = 0.6300

Training Random Forest...
[Parallel(n_jobs=-1)]: Using backend ThreadingBackend with 8 concurrent workers.
[Parallel(n_jobs=-1)]: Done  34 tasks      | elapsed:   21.5s
[Parallel(n_jobs=-1)]: Done 184 tasks      | elapsed:  1.8min
[Parallel(n_jobs=-1)]: Done 300 out of 300 | elapsed:  2.8min finished
Time taken: 172.05s
[Parallel(n_jobs=8)]: Using backend ThreadingBackend with 8 concurrent workers.
[Parallel(n_jobs=8)]: Done  34 tasks      | elapsed:    0.1s
[Parallel(n_jobs=8)]: Done 184 tasks      | elapsed:    0.2s
[Parallel(n_jobs=8)]: Done 300 out of 300 | elapsed:    0.3s finished
Random Forest:
               precision    recall  f1-score   support

         0.0     0.6700    0.8781    0.7600     22742
         1.0     0.5594    0.2635    0.3582     13357

    accuracy                         0.6507     36099
   macro avg     0.6147    0.5708    0.5591     36099
weighted avg     0.6290    0.6507    0.6114     36099





----------------------------------- CNN ------------------------------------

    downsample_args = {
        "strategy": "fraction",
        "value": 0.5,
        "random_state": 42
    }



### VGG7: epochs=50, batch_size=128, lr=1e-3

训练集大小: (198937, 1, 224, 60), 测试集大小: (90247, 1, 224, 60)
训练集标签分布: (array([0., 1.]), array([120217,  78720]))
测试集标签分布: (array([0., 1.]), array([56878, 33369]))

56878 / 90247 = 0.6302



==== 第1次实验 ====

评估 CNN...
预测结果对比 (classification_report):
              precision    recall  f1-score   support

         0.0     0.7373    0.8116    0.7726     56878
         1.0     0.6122    0.5070    0.5546     33369

    accuracy                         0.6990     90247
   macro avg     0.6747    0.6593    0.6636     90247
weighted avg     0.6910    0.6990    0.6920     90247

M_VGG7_e50_b_128_l1e-3_D_10level_training_plot.png





==== 第2次实验 ====

Epoch 15/50: 100%|█████████████████████████████████████████████████████████████| 1555/1555 [02:37<00:00,  9.88it/s]
Epoch 15: Loss=0.5752 | Val F1=0.7135
Epoch 16/50: 100%|█████████████████████████████████████████████████████████████| 1555/1555 [02:27<00:00, 10.56it/s]
Epoch 16: Loss=0.5727 | Val F1=0.7123
EarlyStopping counter: 1 / 6
Epoch 17/50: 100%|█████████████████████████████████████████████████████████████| 1555/1555 [02:28<00:00, 10.46it/s]
Epoch 17: Loss=0.5711 | Val F1=0.7148
Epoch 18/50: 100%|█████████████████████████████████████████████████████████████| 1555/1555 [02:28<00:00, 10.47it/s]
Epoch 18: Loss=0.5684 | Val F1=0.7114
EarlyStopping counter: 1 / 6
Epoch 19/50: 100%|█████████████████████████████████████████████████████████████| 1555/1555 [02:27<00:00, 10.54it/s]
Epoch 19: Loss=0.5664 | Val F1=0.7128
EarlyStopping counter: 2 / 6
Epoch 20/50: 100%|█████████████████████████████████████████████████████████████| 1555/1555 [02:28<00:00, 10.50it/s]
Epoch 20: Loss=0.5641 | Val F1=0.7105
EarlyStopping counter: 3 / 6
Epoch 21/50: 100%|█████████████████████████████████████████████████████████████| 1555/1555 [02:28<00:00, 10.45it/s]
Epoch 21: Loss=0.5619 | Val F1=0.7045
EarlyStopping counter: 4 / 6
Epoch 22/50: 100%|█████████████████████████████████████████████████████████████| 1555/1555 [02:27<00:00, 10.52it/s]
Epoch 22: Loss=0.5588 | Val F1=0.7011
EarlyStopping counter: 5 / 6
Epoch 23/50: 100%|█████████████████████████████████████████████████████████████| 1555/1555 [02:27<00:00, 10.55it/s]
Epoch 23: Loss=0.5557 | Val F1=0.7109
EarlyStopping counter: 6 / 6
触发 EarlyStopping，停止训练
模型已保存到: M_VGG7_e50_b128_l0.001_D_10level.pt
训练曲线已保存为:  M_VGG7_e50_b128_l0.001_D_10level_training_plot.png
评估 CNN...
预测结果对比 (classification_report):
              precision    recall  f1-score   support

         0.0     0.7666    0.7320    0.7489     56878
         1.0     0.5758    0.6202    0.5972     33369

    accuracy                         0.6906     90247
   macro avg     0.6712    0.6761    0.6730     90247
weighted avg     0.6961    0.6906    0.6928     90247






### VGG7: epochs=50, batch_size=128, lr=1e-4

==== 第1次实验 ====

Epoch 34/50: 100%|███████████████████████████████████████████████████████████| 1555/1555 [03:06<00:00,  8.34it/s]
Epoch 34: Loss=0.5862 | Val F1=0.7073
EarlyStopping counter: 7 / 8
Epoch 35/50: 100%|███████████████████████████████████████████████████████████| 1555/1555 [03:07<00:00,  8.31it/s]
Epoch 35: Loss=0.5854 | Val F1=0.7079
EarlyStopping counter: 8 / 8
触发 EarlyStopping，停止训练
模型已保存到: M_VGG7_e50_b128_l0.0001_D_10level.pt
训练曲线已保存为:  M_VGG7_e50_b128_l0.0001_D_10level_training_plot.png
评估 CNN...
预测结果对比 (classification_report):
              precision    recall  f1-score   support

         0.0     0.7789    0.6789    0.7255     56878
         1.0     0.5510    0.6716    0.6053     33369

    accuracy                         0.6762     90247
   macro avg     0.6649    0.6752    0.6654     90247
weighted avg     0.6946    0.6762    0.6810     90247




==== 第2次实验 ====


Epoch 46: Loss=0.5806 | Val F1=0.7072
EarlyStopping counter: 3 / 8
Epoch 47/50: 100%|███████████████████████████████████████████████████████████| 1555/1555 [03:01<00:00,  8.55it/s]
Epoch 47: Loss=0.5801 | Val F1=0.7093
EarlyStopping counter: 4 / 8
Epoch 48/50: 100%|███████████████████████████████████████████████████████████| 1555/1555 [03:01<00:00,  8.56it/s]
Epoch 48: Loss=0.5798 | Val F1=0.7076
EarlyStopping counter: 5 / 8
Epoch 49/50: 100%|███████████████████████████████████████████████████████████| 1555/1555 [03:01<00:00,  8.55it/s]
Epoch 49: Loss=0.5793 | Val F1=0.7101
EarlyStopping counter: 6 / 8
Epoch 50/50: 100%|█████████████████████████████████████████████████████████████| 1555/1555 [03:01<00:00,  8.55it/s]
Epoch 50: Loss=0.5788 | Val F1=0.7116
EarlyStopping counter: 7 / 8
模型已保存到: M_VGG7_e50_b128_l0.0001_D_10level.pt
训练曲线已保存为:  M_VGG7_e50_b128_l0.0001_D_10level_training_plot.png
评估 CNN...
预测结果对比 (classification_report):
              precision    recall  f1-score   support

         0.0     0.7666    0.7341    0.7500     56878
         1.0     0.5773    0.6191    0.5975     33369

    accuracy                         0.6916     90247
   macro avg     0.6720    0.6766    0.6737     90247
weighted avg     0.6966    0.6916    0.6936     90247




### BinaryCNN_3: epochs=50, batch_size=128, lr=1e-3

==== 第1次实验 ====

Epoch 12/50: 100%|█████████████████████████████████████████████████████████████| 1555/1555 [03:29<00:00,  7.43it/s]
Epoch 12: Loss=0.5865 | Val F1=0.7053
Epoch 13/50: 100%|█████████████████████████████████████████████████████████████| 1555/1555 [03:27<00:00,  7.49it/s]
Epoch 13: Loss=0.5842 | Val F1=0.6974
EarlyStopping counter: 1 / 6
Epoch 14/50: 100%|█████████████████████████████████████████████████████████████| 1555/1555 [03:26<00:00,  7.54it/s]
